[2020-10-29 04:16:26,704] {taskinstance.py:670} INFO - Dependencies all met for <TaskInstance: weather-alert-source-data.docker_command 2020-10-29T03:00:00+00:00 [queued]>
[2020-10-29 04:16:26,823] {taskinstance.py:670} INFO - Dependencies all met for <TaskInstance: weather-alert-source-data.docker_command 2020-10-29T03:00:00+00:00 [queued]>
[2020-10-29 04:16:26,825] {taskinstance.py:880} INFO - 
--------------------------------------------------------------------------------
[2020-10-29 04:16:26,828] {taskinstance.py:881} INFO - Starting attempt 1 of 2
[2020-10-29 04:16:26,830] {taskinstance.py:882} INFO - 
--------------------------------------------------------------------------------
[2020-10-29 04:16:26,961] {taskinstance.py:901} INFO - Executing <Task(DockerOperator): docker_command> on 2020-10-29T03:00:00+00:00
[2020-10-29 04:16:26,967] {standard_task_runner.py:54} INFO - Started process 465 to run task
[2020-10-29 04:16:27,384] {standard_task_runner.py:77} INFO - Running: ['airflow', 'run', 'weather-alert-source-data', 'docker_command', '2020-10-29T03:00:00+00:00', '--job_id', '9', '--pool', 'default_pool', '--raw', '-sd', 'DAGS_FOLDER/weather-alert-dag.py', '--cfg_path', '/tmp/tmpiqa5cyzi']
[2020-10-29 04:16:27,395] {standard_task_runner.py:78} INFO - Job 9: Subtask docker_command
[2020-10-29 04:16:27,588] {logging_mixin.py:112} INFO - Running %s on host %s <TaskInstance: weather-alert-source-data.docker_command 2020-10-29T03:00:00+00:00 [running]> 37c7ce38cfab
[2020-10-29 04:16:27,845] {taskinstance.py:1150} ERROR - load_config() got an unexpected keyword argument 'config_dict'
Traceback (most recent call last):
  File "/home/airflow/.local/lib/python3.6/site-packages/airflow/models/taskinstance.py", line 984, in _run_raw_task
    result = task_copy.execute(context=context)
  File "/home/airflow/.local/lib/python3.6/site-packages/airflow/operators/docker_operator.py", line 263, in execute
    tls=tls_config
  File "/usr/local/lib/python3.6/site-packages/docker/api/client.py", line 126, in __init__
    config_dict=self._general_configs, credstore_env=credstore_env,
TypeError: load_config() got an unexpected keyword argument 'config_dict'
[2020-10-29 04:16:27,865] {taskinstance.py:1194} INFO - Marking task as UP_FOR_RETRY. dag_id=weather-alert-source-data, task_id=docker_command, execution_date=20201029T030000, start_date=20201029T041626, end_date=20201029T041627
[2020-10-29 04:16:31,695] {local_task_job.py:102} INFO - Task exited with return code 1
