[2020-10-29 04:16:18,899] {taskinstance.py:670} INFO - Dependencies all met for <TaskInstance: weather-alert-source-data.docker_command 2020-10-29T01:00:00+00:00 [queued]>
[2020-10-29 04:16:19,382] {taskinstance.py:670} INFO - Dependencies all met for <TaskInstance: weather-alert-source-data.docker_command 2020-10-29T01:00:00+00:00 [queued]>
[2020-10-29 04:16:19,384] {taskinstance.py:880} INFO - 
--------------------------------------------------------------------------------
[2020-10-29 04:16:19,385] {taskinstance.py:881} INFO - Starting attempt 1 of 2
[2020-10-29 04:16:19,386] {taskinstance.py:882} INFO - 
--------------------------------------------------------------------------------
[2020-10-29 04:16:19,476] {taskinstance.py:901} INFO - Executing <Task(DockerOperator): docker_command> on 2020-10-29T01:00:00+00:00
[2020-10-29 04:16:19,486] {standard_task_runner.py:54} INFO - Started process 448 to run task
[2020-10-29 04:16:20,758] {standard_task_runner.py:77} INFO - Running: ['airflow', 'run', 'weather-alert-source-data', 'docker_command', '2020-10-29T01:00:00+00:00', '--job_id', '5', '--pool', 'default_pool', '--raw', '-sd', 'DAGS_FOLDER/weather-alert-dag.py', '--cfg_path', '/tmp/tmpndsrnhf7']
[2020-10-29 04:16:20,805] {standard_task_runner.py:78} INFO - Job 5: Subtask docker_command
[2020-10-29 04:16:21,643] {logging_mixin.py:112} INFO - Running %s on host %s <TaskInstance: weather-alert-source-data.docker_command 2020-10-29T01:00:00+00:00 [running]> 37c7ce38cfab
[2020-10-29 04:16:22,192] {taskinstance.py:1150} ERROR - load_config() got an unexpected keyword argument 'config_dict'
Traceback (most recent call last):
  File "/home/airflow/.local/lib/python3.6/site-packages/airflow/models/taskinstance.py", line 984, in _run_raw_task
    result = task_copy.execute(context=context)
  File "/home/airflow/.local/lib/python3.6/site-packages/airflow/operators/docker_operator.py", line 263, in execute
    tls=tls_config
  File "/usr/local/lib/python3.6/site-packages/docker/api/client.py", line 126, in __init__
    config_dict=self._general_configs, credstore_env=credstore_env,
TypeError: load_config() got an unexpected keyword argument 'config_dict'
[2020-10-29 04:16:22,199] {taskinstance.py:1194} INFO - Marking task as UP_FOR_RETRY. dag_id=weather-alert-source-data, task_id=docker_command, execution_date=20201029T010000, start_date=20201029T041618, end_date=20201029T041622
[2020-10-29 04:16:23,207] {local_task_job.py:102} INFO - Task exited with return code 1
