[2020-10-29 04:24:47,971] {taskinstance.py:670} INFO - Dependencies all met for <TaskInstance: weather-alert-source-data.docker_command 2020-10-29T04:24:38.810938+00:00 [queued]>
[2020-10-29 04:24:48,024] {taskinstance.py:670} INFO - Dependencies all met for <TaskInstance: weather-alert-source-data.docker_command 2020-10-29T04:24:38.810938+00:00 [queued]>
[2020-10-29 04:24:48,028] {taskinstance.py:880} INFO - 
--------------------------------------------------------------------------------
[2020-10-29 04:24:48,028] {taskinstance.py:881} INFO - Starting attempt 1 of 2
[2020-10-29 04:24:48,028] {taskinstance.py:882} INFO - 
--------------------------------------------------------------------------------
[2020-10-29 04:24:48,051] {taskinstance.py:901} INFO - Executing <Task(DockerOperator): docker_command> on 2020-10-29T04:24:38.810938+00:00
[2020-10-29 04:24:48,054] {standard_task_runner.py:54} INFO - Started process 398 to run task
[2020-10-29 04:24:48,124] {standard_task_runner.py:77} INFO - Running: ['airflow', 'run', 'weather-alert-source-data', 'docker_command', '2020-10-29T04:24:38.810938+00:00', '--job_id', '21', '--pool', 'default_pool', '--raw', '-sd', 'DAGS_FOLDER/weather-alert-dag.py', '--cfg_path', '/tmp/tmpp69fe2of']
[2020-10-29 04:24:48,126] {standard_task_runner.py:78} INFO - Job 21: Subtask docker_command
[2020-10-29 04:24:48,301] {logging_mixin.py:112} INFO - Running %s on host %s <TaskInstance: weather-alert-source-data.docker_command 2020-10-29T04:24:38.810938+00:00 [running]> 26449acb70c3
[2020-10-29 04:24:48,384] {taskinstance.py:1150} ERROR - Error while fetching server API version: ('Connection aborted.', FileNotFoundError(2, 'No such file or directory'))
Traceback (most recent call last):
  File "/home/airflow/.local/lib/python3.6/site-packages/urllib3/connectionpool.py", line 677, in urlopen
    chunked=chunked,
  File "/home/airflow/.local/lib/python3.6/site-packages/urllib3/connectionpool.py", line 392, in _make_request
    conn.request(method, url, **httplib_request_kw)
  File "/usr/local/lib/python3.6/http/client.py", line 1287, in request
    self._send_request(method, url, body, headers, encode_chunked)
  File "/usr/local/lib/python3.6/http/client.py", line 1333, in _send_request
    self.endheaders(body, encode_chunked=encode_chunked)
  File "/usr/local/lib/python3.6/http/client.py", line 1282, in endheaders
    self._send_output(message_body, encode_chunked=encode_chunked)
  File "/usr/local/lib/python3.6/http/client.py", line 1042, in _send_output
    self.send(msg)
  File "/usr/local/lib/python3.6/http/client.py", line 980, in send
    self.connect()
  File "/usr/local/lib/python3.6/site-packages/docker/transport/unixconn.py", line 43, in connect
    sock.connect(self.unix_socket)
FileNotFoundError: [Errno 2] No such file or directory

During handling of the above exception, another exception occurred:

Traceback (most recent call last):
  File "/home/airflow/.local/lib/python3.6/site-packages/requests/adapters.py", line 449, in send
    timeout=timeout
  File "/home/airflow/.local/lib/python3.6/site-packages/urllib3/connectionpool.py", line 727, in urlopen
    method, url, error=e, _pool=self, _stacktrace=sys.exc_info()[2]
  File "/home/airflow/.local/lib/python3.6/site-packages/urllib3/util/retry.py", line 403, in increment
    raise six.reraise(type(error), error, _stacktrace)
  File "/home/airflow/.local/lib/python3.6/site-packages/urllib3/packages/six.py", line 734, in reraise
    raise value.with_traceback(tb)
  File "/home/airflow/.local/lib/python3.6/site-packages/urllib3/connectionpool.py", line 677, in urlopen
    chunked=chunked,
  File "/home/airflow/.local/lib/python3.6/site-packages/urllib3/connectionpool.py", line 392, in _make_request
    conn.request(method, url, **httplib_request_kw)
  File "/usr/local/lib/python3.6/http/client.py", line 1287, in request
    self._send_request(method, url, body, headers, encode_chunked)
  File "/usr/local/lib/python3.6/http/client.py", line 1333, in _send_request
    self.endheaders(body, encode_chunked=encode_chunked)
  File "/usr/local/lib/python3.6/http/client.py", line 1282, in endheaders
    self._send_output(message_body, encode_chunked=encode_chunked)
  File "/usr/local/lib/python3.6/http/client.py", line 1042, in _send_output
    self.send(msg)
  File "/usr/local/lib/python3.6/http/client.py", line 980, in send
    self.connect()
  File "/usr/local/lib/python3.6/site-packages/docker/transport/unixconn.py", line 43, in connect
    sock.connect(self.unix_socket)
urllib3.exceptions.ProtocolError: ('Connection aborted.', FileNotFoundError(2, 'No such file or directory'))

During handling of the above exception, another exception occurred:

Traceback (most recent call last):
  File "/usr/local/lib/python3.6/site-packages/docker/api/client.py", line 205, in _retrieve_server_version
    return self.version(api_version=False)["ApiVersion"]
  File "/usr/local/lib/python3.6/site-packages/docker/api/daemon.py", line 181, in version
    return self._result(self._get(url), json=True)
  File "/usr/local/lib/python3.6/site-packages/docker/utils/decorators.py", line 46, in inner
    return f(self, *args, **kwargs)
  File "/usr/local/lib/python3.6/site-packages/docker/api/client.py", line 228, in _get
    return self.get(url, **self._set_request_timeout(kwargs))
  File "/home/airflow/.local/lib/python3.6/site-packages/requests/sessions.py", line 543, in get
    return self.request('GET', url, **kwargs)
  File "/home/airflow/.local/lib/python3.6/site-packages/requests/sessions.py", line 530, in request
    resp = self.send(prep, **send_kwargs)
  File "/home/airflow/.local/lib/python3.6/site-packages/requests/sessions.py", line 643, in send
    r = adapter.send(request, **kwargs)
  File "/home/airflow/.local/lib/python3.6/site-packages/requests/adapters.py", line 498, in send
    raise ConnectionError(err, request=request)
requests.exceptions.ConnectionError: ('Connection aborted.', FileNotFoundError(2, 'No such file or directory'))

During handling of the above exception, another exception occurred:

Traceback (most recent call last):
  File "/home/airflow/.local/lib/python3.6/site-packages/airflow/models/taskinstance.py", line 984, in _run_raw_task
    result = task_copy.execute(context=context)
  File "/home/airflow/.local/lib/python3.6/site-packages/airflow/operators/docker_operator.py", line 263, in execute
    tls=tls_config
  File "/usr/local/lib/python3.6/site-packages/docker/api/client.py", line 188, in __init__
    self._version = self._retrieve_server_version()
  File "/usr/local/lib/python3.6/site-packages/docker/api/client.py", line 213, in _retrieve_server_version
    'Error while fetching server API version: {0}'.format(e)
docker.errors.DockerException: Error while fetching server API version: ('Connection aborted.', FileNotFoundError(2, 'No such file or directory'))
[2020-10-29 04:24:48,449] {taskinstance.py:1194} INFO - Marking task as UP_FOR_RETRY. dag_id=weather-alert-source-data, task_id=docker_command, execution_date=20201029T042438, start_date=20201029T042447, end_date=20201029T042448
[2020-10-29 04:24:52,984] {local_task_job.py:102} INFO - Task exited with return code 1
